Workbook

Sheet linhas
A1: P.7 | B1: Importação de bens e serviços | C1: 001 | D1: =EXACT(B1,E1) -> TRUE | E1: Importação de bens e serviços
A2: P.6 | B2: Exportação de bens e serviços | C2: 002 | D2: =EXACT(B2,E2) -> TRUE | E2: Exportação de bens e serviços
A3: P.1 | B3: Produção | C3: 003 | D3: =EXACT(B3,E3) -> TRUE | E3: Produção
A4: P.11 | B4: Produção mercantil | C4: 004 | D4: =EXACT(B4,E4) -> TRUE | E4: Produção mercantil
A5: P.12 | B5: Produção não-mercantil | C5: 005 | D5: =EXACT(B5,E5) -> TRUE | E5: Produção não-mercantil
A6: P.2 | B6: Consumo intermediário | C6: 006 | D6: =EXACT(B6,E6) -> TRUE | E6: Consumo intermediário
A7: D.21-D.31 | B7: Impostos, líquidos de subsídios, sobre produtos | C7: 007 | D7: =EXACT(B7,E7) -> TRUE | E7: Impostos, líquidos de subsídios, sobre produtos
A8: S.1 | B8: Valor adicionado bruto/Produto interno bruto | C8: 008 | D8: =EXACT(B8,E8) -> TRUE | E8: Valor adicionado bruto/Produto interno bruto
A9: S.11 | B9: Saldo externo de bens e serviços | C9: 009 | D9: =EXACT(B9,E9) -> TRUE | E9: Saldo externo de bens e serviços
A10: D.1 | B10: Remuneração dos empregados | C10: 010 | D10: =EXACT(B10,E10) -> TRUE | E10: Remuneração dos empregados
A11: D.11 | B11: Ordenados e salários | C11: 011 | D11: =EXACT(B11,E11) -> TRUE | E11: Ordenados e salários
A12: D.12 | B12: Contribuições sociais dos empregadores | C12: 012 | D12: =EXACT(B12,E12) -> TRUE | E12: Contribuições sociais dos empregadores
... A34: D.62 | B34: Benefícios sociais, exceto transferências sociais em espécie | C34: 034 | D34: =EXACT(B34,E34) -> TRUE | E34: Benefícios sociais, exceto transferências sociais em espécie
A35: D.621 | C35: 035 | D35: =EXACT(B35,E35) -> FALSE | E35: Benefícios de seguridade social em numerário
A36: D.622 | B36: Benefícios sociais com constituição de fundos | C36: 036 | D36: =EXACT(B36,E36) -> TRUE | E36: Benefícios sociais com constituição de fundos
A37: D.623 | B37: Benefícios sociais sem constituição de fundos | C37: 037 | D37: =EXACT(B37,E37) -> TRUE | E37: Benefícios sociais sem constituição de fundos
A38: D.624 | B38: Benefícios de assistência social em numerário | C38: 038 | D38: =EXACT(B38,E38) -> TRUE | E38: Benefícios de assistência social em numerário
A39: D.7 | B39: Outras transferências correntes | C39: 039 | D39: =EXACT(B39,E39) -> TRUE | E39: Outras transferências correntes
A40: D.71 | B40: Prêmios líquidos de seguros não-vida | C40: 040 | D40: =EXACT(B40,E40) -> FALSE | E40: Prêmios líquidos de seguros não-vida
A41: D.72 | B41: Indenizações de seguros não-vida | C41: 041 | D41: =EXACT(B41,E41) -> FALSE | E41: Indenizações de seguros não-vida
A42: D.73 | B42: Transferências correntes entre administrações públicas | C42: 042 | D42: =EXACT(B42,E42) -> FALSE | E42: Transferências correntes entre administrações públicas
A43: D.74 | B43: Cooperação Internacional | C43: 043 | D43: =EXACT(B43,E43) -> FALSE | E43: Cooperação Internacional
A44: D.75 | B44: Transferências correntes diversas | C44: 044 | D44: =EXACT(B44,E44) -> FALSE | E44: Transferências correntes diversas
A45: S.6 | B45: Renda disponível bruta | C45: 045 | D45: =EXACT(B45,E45) -> TRUE | E45: Renda disponível bruta
A46: D.63 | B46: Transferências sociais em espécie | C46: 046 | D46: =EXACT(B46,E46) -> TRUE | E46: Transferências sociais em espécie
A47: B.7 | B47: Renda disponível bruta ajustada | C47: 047 | D47: =EXACT(B47,E47) -> FALSE | E47: Renda disponível bruta ajustada
... A62: S.10.1 | B62: Variações do patrimônio líquido resultantes de poupança e da transferência de capital | C62: 062 | D62: =EXACT(B62,E62) -> TRUE | E62: Variações do patrimônio líquido resultantes de poupança e da transferência de capital

Sheet setores
A1: 0S1 | B1: Total da economia
A2: 0S1001 | B2: Empresas não financeiras
A3: 0S1002FIN | B3: Empresas financeiras
A4: 0S1002SEG | B4: Seguro
A5: 0S1003 | B5: Administração pública
A6: 0S1004 | B6: Famílias
A7: 0S1005 | B7: Instituições s/ fins lucrativ a serviço das fam.
A8: 0S2 | B8: Resto do mundo

Sheet CEI
A1: Contas econômicas integradas - 2020
A3: Contas | B3: Total | C3: Registros correspondentes à | E3: S.1 Total da economia | F3: S.15 Insti- tuições sem fins de lucro a serviço das famílias | G3: S.14 Famílias | H3: S.13 Governo Geral | I3: S.12 Empresas finan- ceiras | J3: S.11 Empresas não- finan- ceiras | K3: Códigos | L3: Transações e saldos | M3: S.11 Empresas não- finan- ceiras | N3: S.12 Empresas finan- ceiras | O3: S.13 Governo Geral | P3: S.14 Famílias | Q3: S.15 Insti- tuições sem fins de lucro a serviço das famílias | R3: S.1 Total da economia | S3: Registros correspondentes à | U3: Total | V3: Contas
C4: Conta de bens e serviços (recursos) | D4: Conta do resto do mundo | S4: Conta do resto do mundo | T4: Conta de bens e serviços (usos)
A7: Contas correntes (1 000 000 R$) | M7: Contas correntes (1 000 000 R$)
A8: Usos | G8: 5034849 | H8: 1039939 | M8: Recursos
A9: 1. Produção/ conta externa de bens e serviços | B9: 1206009 | C9: 1206009 | D9: 0 | E9: 0 | F9: 0 | G9: 0 | H9: 0 | I9: 0 | J9: 0 | K9: P.7 | L9: Importação de bens e serviços | M9: 0 | N9: 0 | O9: 0 | P9: 0 | Q9: 0 | R9: 0 | S9: 1206009 | T9: 0 | U9: 1206009 | V9: 1. Produção/ conta externa de bens e serviços
B10: 1252049 | C10: 0 | D10: 1252049 | E10: 0 | F10: 0 | G10: 0 | H10: 0 | I10: 0 | J10: 0 | K10: P.6 | L10: Exportação de bens e serviços | M10: 0 | N10: 0 | O10: 0 | P10: 0 | Q10: 0 | R10: 0 | S10: 0 | T10: 1252049 | U10: 1252049
B11: 13306199 | C11: 13306199 | D11: 0 | E11: 0 | F11: 0 | G11: 0 | H11: 0 | I11: 0 | J11: 0 | K11: P.1 | L11: Produção | M11: 8940104 | N11: 695746 | O11: 1537130 | P11: 1961389 | Q11: 171830 | R11: 13306199 | S11: 0 | T11: 0 | U11: 13306199
B12: 11007523 | C12: 11007523 | D12: 0 | E12: 0 | F12: 0 | G12: 0 | H12: 0 | I12: 0 | J12: 0 | K12: P.11 | L12: Produção mercantil | M12: 8865336 | N12: 692217 | O12: 47224 | P12: 1335972 | Q12: 66774 | R12: 11007523 | S12: 0 | T12: 0 | U12: 11007523
B13: 2298676 | C13: 2298676 | D13: 0 | E13: 0 | F13: 0 | G13: 0 | H13: 0 | I13: 0 | J13: 0 | K13: P.13 | L13: Produção não-mercantil | M13: 74768 | N13: 3529 | O13: 1489906 | P13: 625417 | Q13: 105056 | R13: 2298676 | S13: 0 | T13: 0 | U13: 2298676
B14: 6711262 | C14: 0 | D14: 0 | E14: 6711262 | F14: 107730 | G14: 610289 | H14: 390230 | I14: 244573 | J14: 5358440 | K14: P.2 | L14: Consumo intermediário | M14: 0 | N14: 0 | O14: 0 | P14: 0 | Q14: 0 | R14: 0 | S14: 0 | T14: 6711262 | U14: 6711262
B15: 1014660 | C15: 1014660 | D15: 0 | E15: 0 | F15: 0 | G15: 0 | H15: 0 | I15: 0 | J15: 0 | K15: D.21-D.31 | L15: Impostos, líquidos de subsídios, sobre produtos | M15: 0 | N15: 0 | O15: 0 | P15: 0 | Q15: 0 | R15: 1014660 | S15: 0 | T15: 0 | U15: 1014660
B16: 7609597 | C16: 0 | D16: 0 | E16: 7609597 | F16: 64100 | G16: 1351100 | H16: 1146900 | I16: 451173 | J16: 3581664 | K16: B.1 | L16: Valor adicionado bruto/Produto interno bruto (1) | M16: 3581664 | N16: 451173 | O16: 1146900 | P16: 1351100 | Q16: 64100 | R16: 7609597 | S16: 0 | T16: 0 | U16: 7609597 | V16: 2.1.1. Geração da renda
B17: -46040 | C17: 0 | D17: -46040 | E17: 0 | F17: 0 | G17: 0 | H17: 0 | I17: 0 | J17: 0 | K17: B.11 | L17: Saldo externo de bens e serviços | M17: 0 | N17: 0 | O17: 0 | P17: 0 | Q17: 0 | R17: 0 | S17: -46040 | T17: 0 | U17: -46040
A18: 2.1.1. Geração da renda | B18: 3193644 | C18: 0 | D18: 1301 | E18: 3192343 | F18: 58323 | G18: 125701 | H18: 1029004 | I18: 181149 | J18: 1798166 | K18: D.1 | L18: Remuneração dos empregados | M18: 0 | N18: 0 | O18: 0 | P18: 3192936 | Q18: 0 | R18: 3192936 | S18: 708 | T18: 0 | U18: 3193644 | V18: 2.1.2. Alocação da renda primária
B19: 2533262 | C19: 0 | D19: 1301 | E19: 2531961 | F19: 49516 | G19: 122479 | H19: 780730 | I19: 140138 | J19: 1439098 | K19: D.11 | L19: Salários | M19: 0 | N19: 0 | O19: 0 | P19: 2532554 | Q19: 0 | R19: 2532554 | S19: 708 | T19: 0 | U19: 2533262
B20: 660382 | C20: 0 | D20: 0 | E20: 660382 | F20: 8807 | G20: 3222 | H20: 248274 | I20: 41011 | J20: 359068 | K20: D.12 | L20: Contribuições sociais dos empregadores | M20: 0 | N20: 0 | O20: 0 | P20: 660382 | Q20: 0 | R20: 660382 | S20: 0 | T20: 0 | U20: 660382
B21: 562617 | C21: 0 | D21: 0 | E21: 562617 | F21: 8807 | G21: 3222 | H21: 150509 | I21: 41011 | J21: 359068 | K21: D.121 | L21: Contribuições sociais efetivas | M21: 0 | N21: 0 | O21: 0 | P21: 562617 | Q21: 0 | R21: 562617 | S21: 0 | T21: 0 | U21: 562617
B22: 97765 | C22: 0 | D22: 0 | E22: 97765 | F22: 0 | G22: 0 | H22: 97765 | I22: 0 | J22: 0 | K22: D.122 | L22: Contribuições sociais imputadas | M22: 0 | N22: 0 | O22: 0 | P22: 97765 | Q22: 0 | R22: 97765 | S22: 0 | T22: 0 | U22: 97765
B23: 1101051 | C23: 0 | D23: 0 | E23: 1101051 | F23: 1037 | G23: -2272 | H23: 278 | I23: 9262 | J23: 78086 | K23: D.2-D.3 | L23: Impostos, líquidos de subsídios, sobre a produção e a importação | M23: 0 | N23: 0 | O23: 1101051 | P23: 0 | Q23: 0 | R23: 1101051 | S23: 0 | T23: 0 | U23: 1101051
B24: 1014660 | C24: 0 | D24: 0 | E24: 1014660 | F24: 0 | G24: 0 | H24: 0 | I24: 0 | J24: 0 | K24: D.21-D.31 | L24: Impostos, líquidos de subsídios, sobre produtos | M24: 0 | N24: 0 | O24: 1014660 | P24: 0 | Q24: 0 | R24: 1014660 | S24: 0 | T24: 0 | U24: 1014660
B25: 86391 | C25: 0 | D25: 0 | E25: 86391 | F25: 1037 | G25: -2272 | H25: 278 | I25: 9262 | J25: 78086 | K25: D.29-D.39 | L25: Outros impostos, líquidos de subsídios, sobre a produção | M25: 0 | N25: 0 | O25: 86391 | P25: 0 | Q25: 0 | R25: 86391 | S25: 0 | T25: 0 | U25: 86391
B26: 2682839 | C26: =B16-B18-B23+B17 -> 3268862 | D26: 0 | E26: 2682839 | F26: 4740 | G26: 594307 | H26: =O16-H18-H23 -> 117618 | I26: =I16-I18-I23 -> 260762 | J26: =M16-J18-J23 -> 1705412 | K26: B.2 | L26: Excedente operacional bruto | M26: 1705412 | N26: 260762 | O26: 117618 | P26: 594307 | Q26: 4740 | R26: 2682839 | S26: 0 | T26: 0 | U26: 2682839
B27: 633364 | C27: =SUM(B26:B27) -> 3316203 | D27: 0 | E27: 633364 | F27: 0 | G27: 633364 | I27: 0 | J27: 0 | K27: B.3 | L27: Rendimento misto bruto (rendimento de autônomos) | M27: 0 | N27: 0 | O27: 0 | P27: 633364 | Q27: 0 | R27: 633364 | S27: 0 | T27: 0 | U27: 633364
A28: 2.1.2. Alocação da renda primária | B28: 3029954 | C28: 0 | D28: 100439 | E28: 2929515 | F28: 116 | G28: 205684 | H28: 446981 | I28: 1323947 | J28: 952787 | K28: D.4 | L28: Rendas de propriedade | M28: 322910 | N28: 1348503 | O28: 268251 | P28: 819926 | Q28: 10573 | R28: 2770163 | S28: 259791 | T28: 0 | U28: 3029954
B29: 2028056 | D29: 32573 | E29: 1995483 | F29: 116 | G29: 205027 | H29: 446981 | I29: 1060460 | J29: 282899 | K29: D.41 | L29: Juros | M29: 246213 | N29: 1235025 | O29: 191053 | P29: 239016 | Q29: 10530 | R29: 1921837 | S29: 106219 | T29: 0 | U29: 2028056
B30: 805952 | C30: 0 | D30: 61731 | E30: 744221 | F30: 0 | G30: 0 | H30: 0 | I30: 164460 | J30: 579761 | K30: D.42 | L30: Rendas distribuídas das empresas | M30: 70354 | N30: 86283 | O30: 10278 | P30: 513540 | Q30: 0 | R30: 680455 | S30: 125497 | T30: 0 | U30: 805952
B31: 34173 | C31: 0 | D31: 6135 | E31: 28038 | F31: 0 | G31: 0 | H31: 0 | I31: 3562 | J31: 24476 | K31: D.43 | L31: Lucros reinvestidos de investimento estrangeiro direto | M31: 2842 | N31: 3293 | O31: 0 | P31: 0 | Q31: 0 | R31: 6135 | S31: 28038 | T31: 0 | U31: 34173
B32: 95465 | C32: 0 | D32: 0 | E32: 95465 | F32: 0 | G32: 0 | H32: 0 | I32: 95465 | J32: 0 | K32: D.44 | L32: Desembolsos por rendas de investimentos | M32: 3501 | N32: 23902 | O32: 612 | P32: 67370 | Q32: 43 | R32: 95428 | S32: 37 | T32: 0 | U32: 95465
B33: 6574 | C33: 0 | D33: 0 | E33: 6574 | F33: 0 | G33: 0 | H33: 0 | I33: 6574 | J33: 0 | K33: D.441 | L33: Rendimento de investimentos atribuído a detentores de apólices de seguros | M33: 1186 | N33: 1107 | O33: 65 | P33: 4136 | Q33: 43 | R33: 6537 | S33: 37 | T33: 0 | U33: 6574
B34: 56739 | C34: 0 | D34: 0 | E34: 56739 | F34: 0 | G34: 0 | H34: 0 | I34: 56739 | J34: 0 | K34: D.442 | L34: Rendimento de investimentos a pagar sobre direitos de pensão | M34: 0 | N34: 0 | O34: 0 | P34: 56739 | Q34: 0 | R34: 56739 | S34: 0 | T34: 0 | U34: 56739
B35: 32152 | C35: 0 | D35: 0 | E35: 32152 | F35: 0 | G35: 0 | H35: 0 | I35: 32152 | J35: 0 | K35: D.443 | L35: Rendimento de investimentos atribuído a acionistas de fundos de investimento | M35: 2315 | N35: 22795 | O35: 547 | P35: 6495 | Q35: 0 | R35: 32152 | S35: 0 | T35: 0 | U35: 32152
B36: 66308 | C36: 0 | D36: 0 | E36: 66308 | F36: 0 | G36: 657 | H36: 0 | I36: 0 | J36: 65651 | K36: D.45 | L36: Renda de recursos naturais | M36: 0 | N36: 0 | O36: 66308 | P36: 0 | Q36: 0 | R36: 66308 | S36: 0 | T36: 0 | U36: 66308
B37: 7450838 | C37: 0 | D37: 0 | E37: 7450838 | F37: 15197 | G37: 5034849 | H37: =O16+O23-H18-H23+O28-H28 -> 1039939 | I37: 285318 | J37: 1075535 | K37: B.5 | L37: Saldo das rendas primárias brutas/Renda nacional bruta (2) | M37: 1075535 | N37: 285318 | O37: 1039939 | P37: 5034849 | Q37: 15197 | R37: 7450838 | S37: 0 | T37: 0 | U37: 7450838 | V37: 2.2. Distribuição secundária da renda
A38: 2.2. Distribuição secundária da renda | B38: 625041 | C38: 0 | D38: 0 | E38: 625041 | F38: 584 | G38: 286229 | H38: 365 | I38: 42715 | J38: 295148 | K38: D.5 | L38: Impostos correntes sobre a renda, patrimônio, etc. | M38: 0 | N38: 0 | O38: 625041 | P38: 0 | Q38: 0 | R38: 625041 | S38: 0 | T38: 0 | U38: 625041
B39: 895266 | C39: 0 | D39: 0 | E39: 895266 | F39: 0 | G39: 895266 | H39: 0 | I39: 0 | J39: 0 | K39: D.61 | L39: Contribuições sociais | M39: 0 | N39: 94536 | O39: 800730 | P39: 0 | Q39: 0 | R39: 895266 | S39: 0 | T39: 0 | U39: 895266
B40: 562617 | C40: 0 | D40: 0 | E40: 562617 | F40: 0 | G40: 562617 | H40: 0 | I40: 0 | J40: 0 | K40: D.611 | L40: Contribuições sociais efetivas dos empregadores | M40: 0 | N40: 21236 | O40: 541381 | P40: 0 | Q40: 0 | R40: 562617 | S40: 0 | T40: 0 | U40: 562617
B41: 97765 | C41: 0 | D41: 0 | E41: 97765 | F41: 0 | G41: 97765 | H41: 0 | I41: 0 | J41: 0 | K41: D.612 | L41: Contribuições sociais imputadas dos empregadores | M41: 0 | N41: 0 | O41: 97765 | P41: 0 | Q41: 0 | R41: 97765 | S41: 0 | T41: 0 | U41: 97765
B42: 234884 | C42: 0 | D42: 0 | E42: 234884 | F42: 0 | G42: 234884 | H42: 0 | I42: 0 | J42: 0 | K42: D.613/614 | L42: Contribuições sociais efetivas das famílias/empregados e suplemento às contribuições sociais | M42: 0 | N42: 73300 | O42: 161584 | P42: 0 | Q42: 0 | R42: 234884 | S42: 0 | T42: 0 | U42: 234884
B43: 1827609 | C43: 0 | D43: 0 | E43: 1827609 | F43: 0 | G43: 0 | H43: 1752871 | I43: 74738 | J43: 0 | K43: D.62 | L43: Benefícios sociais, exceto transferências sociais em espécie | M43: 0 | N43: 0 | O43: 0 | P43: 1827609 | Q43: 0 | R43: 1827609 | S43: 0 | T43: 0 | U43: 1827609
...

Sheet CEIResumida
D2: S.14 Famílias | F2: S.13 Governo Geral | H2: S.12 Empresas finan- ceiras | J2: S.11 Empresas não- finan- ceiras | L2: Setor externo
D6: Entrada | E6: Saída | F6: Entrada | G6: Saída | H6: Entrada | I6: Saída | J6: Entrada | K6: Saída | L6: Entrada | M6: Saída
C7: Valor adicionado bruto/Produto interno bruto (1) | D7: =CEI!G16+CEI!F16 -> 1415200 | F7: =CEI!H16 -> 1146900 | H7: =CEI!I16+SimulTRU!I19 -> 518661 | J7: =CEI!J16+CEI!C15-SimulTRU!I19 -> 4528836 | L7: =CEI!S9 -> 1206009 | M7: =CEI!T10 -> 1252049 | N7: =SUM(D7:J7) -> 7609597 | O7: =CEI!B16 -> 7609597
C8: =CEI!L16 -> Valor adicionado bruto/Produto interno bruto (1) | D8: =SUM(CEI!P19:Q19) -> 2532554 | E8: =SUM(CEI!F19:G19) -> 171995 | G8: =CEI!H19 -> 780730 | I8: =CEI!I19 -> 140138 | K8: =CEI!J19 -> 1439098 | L8: =CEI!S18 -> 708 | M8: =CEI!D19 -> 1301 | N8: =D8+F8+H8+J8+L8-M8-K8-I8-G8-E8 -> 0
C9: =CEI!L21 -> Contribuições sociais efetivas | D9: =CEI!P21 -> 562617 | E9: =CEI!F21+CEI!G21 -> 12029 | G9: =CEI!H21 -> 150509 | I9: =CEI!I21 -> 41011 | K9: =CEI!J20 -> 359068 | N9: =D9+F9+H9+J9+L9-M9-K9-I9-G9-E9 -> 0
C10: Contribuições sociais inputadas | D10: =CEI!P22 -> 97765 | G10: =CEI!H22 -> 97765
C11: Impostos, líquidos de subsídios, sobre produtos | F11: =CEI!O24 -> 1014660 | I11: =SimulTRU!I19 -> 67488 | K11: =F11-I11 -> 947172 | N11: =D11+F11+H11+J11+L11-M11-K11-I11-G11-E11 -> 1.4551915e-11
C12: Outros impostos, líquidos de subsídios, sobre a produção | E12: =CEI!G25+CEI!F25 -> -1235 | F12: =CEI!O25 -> 86391 | G12: =CEI!H25 -> 278 | I12: =CEI!I25 -> 9262 | K12: =CEI!J25 -> 78086 | N12: =D12+F12+H12+J12+L12-M12-K12-I12-G12-E12 -> 0
C13: =CEI!L29 -> Juros | D13: =CEI!P29+CEI!Q29 -> 249546 | E13: =SUM(CEI!F29:G29) -> 205143 | F13: =CEI!O29 -> 191053 | G13: =CEI!H29 -> 446981 | H13: =CEI!N29 -> 1235025 | I13: =CEI!I29 -> 1060460 | J13: =CEI!M29 -> 246213 | K13: =CEI!J29 -> 282899 | L13: =CEI!S29 -> 106219 | M13: =CEI!D29 -> 32573 | N13: =D13+F13+H13+J13+L13-M13-K13-I13-G13-E13 -> 0
C14: =CEI!L30 -> Rendas distribuídas das empresas | D14: =SUM(CEI!P30:Q32) -> 580953 | E14: =SUM(CEI!F30:G36) -> 657 | F14: =SUM(CEI!O30:O32)+CEI!O36 -> 77198 | G14: 0 | H14: =CEI!N30+CEI!N31+CEI!N32 -> 113478 | I14: =SUM(CEI!I30:I32) -> 263487 | J14: =CEI!M30+CEI!M31+CEI!M32 -> 76697 | K14: =CEI!J30+CEI!J31+CEI!J36 -> 669888 | L14: =CEI!S30+CEI!S31+CEI!S32 -> 153572 | M14: =CEI!D30+CEI!D31 -> 67866 | N14: =D14+F14+H14+J14+L14-M14-K14-I14-G14-E14 -> 0
C15: =CEI!L31 -> Lucros reinvestidos de investimento estrangeiro direto | N15: =D15+F15+H15+J15+L15-M15-K15-I15-G15-E15 -> 0
C16: =CEI!L32 -> Desembolsos por rendas de investimentos | N16: =D16+F16+H16+J16+L16-M16-K16-I16-G16-E16 -> 0
C17: =CEI!L33 -> Rendimento de investimentos atribuído a detentores de apólices de seguros | N17: =D17+F17+H17+J17+L17-M17-K17-I17-G17-E17 -> 0
C18: =CEI!L37 -> Saldo das rendas primárias brutas/Renda nacional bruta (2) | D18: =SUM(D7:D17)-SUM(E7:E17) -> 5050046 | F18: =SUM(F7:F17)-SUM(G7:G17) -> 1039939 | H18: =SUM(H7:H17)-SUM(I7:I17) -> 285318 | J18: =SUM(J7:J17)-SUM(K7:K17) -> 1075535 | L18: =SUM(L7:L17)-SUM(M7:M17) -> 112719 | N18: =SUM(D18:K18) -> 7450838 | O18: =CEI!E37 -> 7450838
C20: Check | D20: =CEI!F37+CEI!G37 -> 5050046 | F20: =CEI!H37 -> 1039939 | H20: =CEI!I37 -> 285318 | J20: =CEI!J37 -> 1075535 | N20: =SUM(D20:M20) -> 7450838
D21: Entrada | E21: Saída | F21: Entrada | G21: Saída | H21: Entrada | I21: Saída | J21: Entrada | K21: Saída | L21: Entrada | M21: Saída
C22: Impostos correntes sobre a renda, patrimônio, etc. | E22: =SUM(CEI!F38:G38) -> 286813 | F22: =CEI!O38 -> 625041 | G22: =CEI!H38 -> 365 | I22: =CEI!I38 -> 42715 | K22: =CEI!J38 -> 295148 | N22: =D22+F22+H22+J22+L22-M22-K22-I22-G22-E22 -> 0
C23: Contribuições sociais | E23: =CEI!G39+CEI!F39 -> 895266 | F23: =CEI!O39 -> 800730 | H23: =CEI!N39 -> 94536 | N23: =D23+F23+H23+J23+L23-M23-K23-I23-G23-E23 -> 0
C24: Benefícios sociais, exceto transferências sociais em espécie | N24: =D24+F24+H24+J24+L24-M24-K24-I24-G24-E24 -> 0
C25: =CEI!L44 -> Benefícios de seguridade social em numerário | D25: =CEI!P44+CEI!Q44 -> 742258 | F25: =CEI!O44 -> 0 | G25: =CEI!H44 -> 742258 | I25: =CEI!I44 -> 0
C26: =CEI!L45 -> Outros benefícios de seguro social | D26: =CEI!P45+CEI!Q45 -> 670737 | F26: =CEI!O45 -> 0 | G26: =CEI!H45 -> 595999 | I26: =CEI!I45 -> 74738
C27: =CEI!L46 -> Benefícios de assistência social em numerário | D27: =CEI!P46+CEI!Q46 -> 414614 | F27: =CEI!O46 -> 0 | G27: =CEI!H46 -> 414614 | I27: =CEI!I46 -> 0
C28: Outras transferências correntes | D28: =CEI!P47+CEI!Q47 -> 153554 | E28: =CEI!G47+CEI!F47 -> 112621 | F28: =CEI!O47 -> 881244 | G28: =CEI!H47 -> 844896 | H28: =CEI!N47 -> 67100 | I28: =CEI!I47 -> 80387 | J28: =CEI!M47 -> 41947 | K28: =CEI!J47 -> 95043 | L28: =CEI!S47 -> 15517 | M28: =CEI!D47 -> 26415 | N28: =D28+F28+H28+J28+L28-M28-K28-I28-G28-E28 -> 0
C29: Renda nacional disponível bruta | D29: =D18+SUM(D22:D28)-SUM(E22:E28) -> 5736509 | F29: =F18+SUM(F22:F28)-SUM(G22:G28) -> 748822 | H29: =H18+SUM(H22:H28)-SUM(I22:I28) -> 249114 | J29: =J18+SUM(J22:J28)-SUM(K22:K28) -> 727291 | L29: =L18+SUM(L22:L28)-SUM(M22:M28) -> 101821 | N29: =D29+F29+H29+J29+L29-M29-K29-I29-G29-E29 -> 7563557
C30: Check | D30: =CEI!F53+CEI!G53 -> 5736509 | F30: =CEI!H53 -> 748822 | H30: =CEI!I53 -> 249114 | J30: =CEI!J53 -> 727291 | L30: =CEI!D61 -> 101821 | N30: =D30+F30+H30+J30+L30-M30-K30-I30-G30-E30 -> 7563557
D31: Entrada | E31: Saída | F31: Entrada | G31: Saída | H31: Entrada | I31: Saída | J31: Entrada | K31: Saída | L31: Entrada | M31: Saída
C32: Consumo final efetivo | E32: =CEI!G58+CEI!F58 -> 4805004 | G32: =CEI!H58 -> 1532204 | N32: =D32+F32+H32+J32+L32-M32-K32-I32-G32-E32 -> -6337208
C33: Ajustamento pela variação dos direitos de pensão | D33: =CEI!P59 -> 47061 | G33: =CEI!H59 -> 28647 | I33: =CEI!I59 -> 18414 | N33: =D33+F33+H33+J33+L33-M33-K33-I33-G33-E33 -> 0
C34: Poupança bruta | D34: =D29+SUM(D32:D33)-SUM(E32:E33) -> 978566 | F34: =F29+SUM(F32:F33)-SUM(G32:G33) -> -812029 | H34: =H29+SUM(H32:H33)-SUM(I32:I33) -> 230700 | J34: =J29+SUM(J32:J33)-SUM(K32:K33) -> 727291 | L34: =L29+SUM(L32:L33)-SUM(M32:M33) -> 101821 | N34: =D34+F34+H34+J34+L34-M34-K34-I34-G34-E34 -> 1226349
D35: Entrada | E35: Saída | F35: Entrada | G35: Saída | H35: Entrada | I35: Saída | J35: Entrada | K35: Saída | L35: Entrada | M35: Saída
C36: Formação bruta de capital fixo | E36: =CEI!F66+CEI!G66 -> 410010 | G36: =CEI!H66 -> 139686 | I36: =CEI!I66 -> 13718 | K36: =CEI!J66 -> 696813 | N36: =D36+F36+H36+J36+L36-M36-K36-I36-G36-E36 -> -1260227
C37: Variação de estoques | K37: =CEI!J67 -> -33878 | N37: =D37+F37+H37+J37+L37-M37-K37-I37-G37-E37 -> 33878
C38: Aquisições líquidas de cessões de ativos não-produzidos // Transferências | D38: =SUM(CEI!P68:Q70) -> -6284 | E38: =SUM(CEI!F68:G70) -> 0 | F38: =SUM(CEI!O68:O70) -> 27118 | G38: =SUM(CEI!H68:H70) -> -6588 | H38: =SUM(CEI!N68:N71) -> -65 | I38: =SUM(CEI!I68:I70) -> 0 | J38: =SUM(CEI!M68:M70) -> -208 | K38: =SUM(CEI!J68:J70) -> 5866 | L38: =SUM(CEI!S68:S71) -> -20561 | M38: =SUM(CEI!D68:D70) -> 722 | N38: =D38+F38+H38+J38+L38-M38-K38-I38-G38-E38 -> 0
C39: Capacidade (+) / Necessidade(-) líquida de financiamento | D39: =D34+SUM(D36:D38)-SUM(E36:E38) -> 562272 | F39: =F34+SUM(F36:F38)-SUM(G36:G38) -> -918009 | H39: =H34+SUM(H36:H38)-SUM(I36:I38) -> 216917 | J39: =J34+SUM(J36:J38)-SUM(K36:K38) -> 58282 | L39: =L34+SUM(L36:L38)-SUM(M36:M38) -> 80538 | N39: =D39+F39+H39+J39+L39-M39-K39-I39-G39-E39 -> 0
C40: Check | D40: =CEI!F71+CEI!G71 -> 562272 | F40: =CEI!H71 -> -918009 | H40: =CEI!I71 -> 216917 | J40: =CEI!J71 -> 58282 | L40: =CEI!D71 -> 80538 | N40: =SUM(D40:M40) -> 0
D42: S.14 Famílias | F42: S.13 Governo Geral | H42: S.12 Empresas finan- ceiras | J42: S.11 Empresas não- finan- ceiras | L42: Setor externo
D46: Entrada | E46: Saída | F46: Entrada | G46: Saída | H46: Entrada | I46: Saída | J46: Entrada | K46: Saída | L46: Entrada | M46: Saída | O46: VA preço mercado | P46: VA preço básico
C47: Valor adicionado bruto/Produto interno bruto (1) | D47: =D7 -> 1415200 | E47: =E7 -> 0 | F47: =F7 -> 1146900 | G47: =G7 -> 0 | H47: =H7 -> 518661 | I47: =I7 -> 0 | J47: =J7 -> 4528836 | K47: =K7 -> 0 | ... M47: =M7 -> 1252049 | N47: =D47+F47+H47+J47+L47-M47-K47-I47-G47-E47 -> 7563557 | O47: =H47+J47+D47+F47 -> 7609597 | P47: =O47-K51 -> 6662425
C48: Salários | D48: =D8 -> 2532554 | E48: =E8 -> 171995 | F48: =F8 -> 0 | G48: =G8 -> 780730 | H48: =H8 -> 0 | I48: =I8 -> 140138 | J48: =J8 -> 0 | K48: =K8 -> 1439098 | ... M48: =M8 -> 1301 | N48: =D48+F48+H48+J48+L48-M48-K48-I48-G48-E48 -> 0
C49: =C9 -> Contribuições sociais efetivas | D49: =D9 -> 562617 | E49: =E9 -> 12029 | F49: =F9 -> 0 | G49: =G9 -> 150509 | H49: =H9 -> 0 | I49: =I9 -> 41011 | J49: =J9 -> 0 | ... M49: =M9 -> 0 | N49: =D49+F49+H49+J49+L49-M49-K49-I49-G49-E49 -> 0
...

Sheet Python
B1: Household | C1: Household | D1: Gov | E1: Gov | F1: Ffirms | G1: Ffirms | H1: Firms | I1: Firms | J1: ExtSector | K1: ExtSector
B2: Entrada | C2: Saída | D2: Entrada | E2: Saída | F2: Entrada | G2: Saída | H2: Entrada | I2: Saída | J2: Entrada | K2: Saída
A3: Valor adicionado bruto/Produto interno bruto (1) | C3: 0 | E3: 0 | F3: 522038 | G3: 0 | H3: 7087559 | I3: 0 | J3: 1206009 | K3: 1252049
A4: Salários | B4: 2531961 | C4: 0 | D4: 0 | F4: 0 | G4: 140274 | H4: 0 | I4: 2391687 | J4: 0 | K4: 0
A5: Contribuições sociais efetivas | B5: 562617 | C5: 0 | D5: 0 | F5: 0 | G5: 41011 | H5: 0 | I5: 521606 | J5: 0 | K5: 0
A6: Contribuições sociais inputadas | B6: 0 | C6: 0 | D6: 0 | E6: 0 | F6: 0 | G6: 0 | H6: 0 | I6: 0 | J6: 0 | K6: 0
A7: Impostos, líquidos de subsídios, sobre produtos | B7: 0 | C7: 0 | D7: 1014660 | E7: 0 | F7: 0 | G7: 67488 | H7: 0 | I7: 947172 | J7: 0 | K7: 0
A8: Outros impostos, líquidos de subsídios, sobre a produção | B8: 0 | C8: 0 | D8: 86391 | E8: 0 | F8: 0 | G8: 9262 | H8: 0 | I8: 77129 | J8: 0 | K8: 0
A9: Juros | B9: 249546 | C9: 205143 | D9: 191053 | E9: 446981 | F9: 1235025 | G9: 1060460 | H9: 246213 | I9: 282899 | J9: 106219 | K9: 32573
A10: Rendas distribuídas das empresas | B10: 1888670 | C10: 0 | D10: 0 | E10: 0 | F10: 0 | G10: 153250 | H10: 0 | I10: 1821126 | J10: 85706 | K10: 0
A11: Lucros reinvestidos de investimento estrangeiro direto | B11: 0 | C11: 0 | D11: 0 | E11: 0 | F11: 0 | G11: 0 | H11: 0 | I11: 0 | J11: 0 | K11: 0
A12: Desembolsos por rendas de investimentos | B12: 0 | C12: 0 | D12: 0 | E12: 0 | F12: 0 | G12: 0 | H12: 0 | I12: 0 | J12: 0 | K12: 0
A13: Renda de recursos naturais | B13: 0 | C13: 0 | D13: 0 | E13: 0 | F13: 0 | G13: 0 | H13: 0 | I13: 0 | J13: 0 | K13: 0
A14: Impostos correntes sobre a renda, patrimônio, // Contribuições sociais // Outras transferências | B14: 0 | C14: 362776 | D14: 917257 | E14: 0 | F14: 0 | G14: 42715 | H14: 0 | I14: 511766 | J14: 0 | K14: 0
A15: Contribuições sociais | B15: 0 | C15: 895266 | D15: 800730 | E15: 0 | F15: 94536 | G15: 0 | H15: 0 | I15: 0 | J15: 0 | K15: 0
A16: Benefícios de seguridade social em numerário // Seguro desemprego, bolsa família | B16: 1254637 | C16: 0 | D16: 0 | E16: 1254637 | F16: 0 | G16: 0 | H16: 0 | I16: 0 | J16: 0 | K16: 0
A17: Outros benefícios de seguro social // Previdência | B17: 717798 | C17: 0 | D17: 0 | E17: 624646 | F17: 0 | G17: 93152 | H17: 0 | I17: 0 | J17: 0 | K17: 0
... A19: Consumo final efetivo | B19: 0 | C19: 4805004 | D19: 0 | E19: 1532204 | F19: 0 | G19: 0 | H19: 0 | I19: 0 | J19: 0 | K19: 0
A20: Ajustamento pela variação dos direitos de pensão | B20: 0 | C20: 0 | D20: 0 | E20: 0 | F20: 0 | H20: 0 | I20: 0 | J20: 0 | K20: 0
A21: Formação bruta de capital fixo | B21: 0 | C21: 410010 | D21: 0 | E21: 139686 | F21: 0 | G21: 13718 | H21: 0 | I21: 696813 | J21: 0 | K21: 0
A22: Variação de estoques | B22: 0 | C22: 0 | D22: 0 | E22: 0 | F22: 0 | G22: 0 | H22: 0 | I22: -33878 | J22: 0 | K22: 0
A23: Aquisições líquidas de cessões de ativos não-produzidos | B23: 0 | C23: 0 | F23: 0 | G23: 0 | H23: 0 | I23: 0 | J23: 0 | K23: 0
A24: Capacidade (+) / Necessidade(-) líquida de financiamento | B24: =SUM(B3:B23)-SUM(C3:C23) -> 562272 | D24: =SUM(D3:D23)-SUM(E3:E23) -> -918009 | F24: =SUM(F3:F23)-SUM(G3:G23) -> 216917 | H24: =SUM(H3:H23)-SUM(I3:I23) -> 58282 | J24: =SUM(J3:J23)-SUM(K3:K23) -> 80538

Sheet ParâmetrosCEI
C2: S.14 Famílias | E2: S.13 Governo Geral | G2: S.12 Empresas finan- ceiras | I2: S.11 Empresas não- finan- ceiras | K2: Setor externo
C6: Entrada | D6: Saída | E6: Entrada | F6: Saída | G6: Entrada | H6: Saída | I6: Entrada | J6: Saída | K6: Entrada | L6: Saída | N6: VA preço mercado | O6: VA preço básico
B7: Valor adicionado bruto/Produto interno bruto (1) | C7: =CEIResumida!D80 -> 0 | D7: =CEIResumida!E80 -> 0 | E7: =CEIResumida!F80 -> 0 | F7: =CEIResumida!G80 -> 0 | G7: =CEIResumida!H80 -> 522038 | H7: =CEIResumida!I80 -> 0 | I7: =CEIResumida!J80 -> 7087559 | J7: =CEIResumida!K80 -> 0 | ... L7: =CEIResumida!M80 -> 1252049 | N7: =G7+I7 -> 7609597 | O7: =N7-J11 -> 6662425
A8: Tabela de Usos e Recursos - específico por setor - geração de renda | B8: Salários | C8: =CEIResumida!D81 -> 2531961 | D8: =CEIResumida!E81 -> 0 | E8: =CEIResumida!F81 -> 0 | F8: =CEIResumida!G81 -> 0 | G8: =CEIResumida!H81 -> 0 | H8: =CEIResumida!I81 -> 140274 | I8: =CEIResumida!J81 -> 0 | J8: =CEIResumida!K81 -> 2391687 | ... L8: =CEIResumida!M81 -> 0
B9: Contribuições sociais efetivas | C9: =CEIResumida!D82 -> 562617 | D9: =CEIResumida!E82 -> 0 | E9: =CEIResumida!F82 -> 0 | F9: =CEIResumida!G82 -> 0 | G9: =CEIResumida!H82 -> 0 | H9: =CEIResumida!I82 -> 41011 | I9: =CEIResumida!J82 -> 0 | J9: =CEIResumida!K82 -> 521606 | ... L9: =CEIResumida!M82 -> 0
B10: Contribuições sociais inputadas | C10: =CEIResumida!D83 -> 0 | D10: =CEIResumida!E83 -> 0 | E10: =CEIResumida!F83 -> 0 | F10: =CEIResumida!G83 -> 0 | G10: =CEIResumida!H83 -> 0 | H10: =CEIResumida!I83 -> 0 | I10: =CEIResumida!J83 -> 0 | J10: =CEIResumida!K83 -> 0 | ... L10: =CEIResumida!M83 -> 0
B11: Impostos, líquidos de subsídios, sobre produtos | C11: =CEIResumida!D84 -> 0 | D11: =CEIResumida!E84 -> 0 | E11: =CEIResumida!F84 -> 1014660 | F11: =CEIResumida!G84 -> 0 | G11: =CEIResumida!H84 -> 0 | H11: =CEIResumida!I84 -> 67488 | I11: =CEIResumida!J84 -> 0 | J11: =CEIResumida!K84 -> 947172 | ... L11: =CEIResumida!M84 -> 0
B12: Outros impostos, líquidos de subsídios, sobre a produção | C12: =CEIResumida!D85 -> 0 | D12: =CEIResumida!E85 -> 0 | E12: =CEIResumida!F85 -> 86391 | F12: =CEIResumida!G85 -> 0 | G12: =CEIResumida!H85 -> 0 | H12: =CEIResumida!I85 -> 9262 | I12: =CEIResumida!J85 -> 0 | J12: =CEIResumida!K85 -> 77129 | ... L12: =CEIResumida!M85 -> 0
A13: Alocação primária do excedente | B13: Juros | C13: =CEIResumida!D86 -> 249546 | D13: =CEIResumida!E86 -> 205143 | E13: =CEIResumida!F86 -> 191053 | F13: =CEIResumida!G86 -> 446981 | G13: =CEIResumida!H86 -> 1235025 | H13: =CEIResumida!I86 -> 1060460 | I13: =CEIResumida!J86 -> 246213 | J13: =CEIResumida!K86 -> 282899 | ... L13: =CEIResumida!M86 -> 32573
B14: Rendas distribuídas das empresas | C14: =CEIResumida!D87 -> 1888670 | D14: =CEIResumida!E87 -> 0 | E14: =CEIResumida!F87 -> 0 | F14: =CEIResumida!G87 -> 0 | G14: =CEIResumida!H87 -> 0 | H14: =CEIResumida!I87 -> 153250 | I14: =CEIResumida!J87 -> 0 | J14: =CEIResumida!K87 -> 1821126 | ... L14: =CEIResumida!M87 -> 0
B15: Lucros reinvestidos de investimento estrangeiro direto | C15: =CEIResumida!D88 -> 0 | D15: =CEIResumida!E88 -> 0 | E15: =CEIResumida!F88 -> 0 | F15: =CEIResumida!G88 -> 0 | G15: =CEIResumida!H88 -> 0 | H15: =CEIResumida!I88 -> 0 | I15: =CEIResumida!J88 -> 0 | J15: =CEIResumida!K88 -> 0 | ... L15: =CEIResumida!M88 -> 0
B16: Desembolsos por rendas de investimentos | C16: =CEIResumida!D89 -> 0 | D16: =CEIResumida!E89 -> 0 | E16: =CEIResumida!F89 -> 0 | F16: =CEIResumida!G89 -> 0 | G16: =CEIResumida!H89 -> 0 | H16: =CEIResumida!I89 -> 0 | I16: =CEIResumida!J89 -> 0 | J16: =CEIResumida!K89 -> 0 | ... L16: =CEIResumida!M89 -> 0
B17: Renda de recursos naturais | C17: =CEIResumida!D90 -> 0 | D17: =CEIResumida!E90 -> 0 | E17: =CEIResumida!F90 -> 0 | F17: =CEIResumida!G90 -> 0 | G17: =CEIResumida!H90 -> 0 | H17: =CEIResumida!I90 -> 0 | I17: =CEIResumida!J90 -> 0 | J17: =CEIResumida!K90 -> 0 | ... L17: =CEIResumida!M90 -> 0
A18: Alocação secundária | B18: Impostos correntes sobre a renda, patrimônio, // Contribuições sociais // Outras transferências | C18: =CEIResumida!D91 -> 0 | D18: =CEIResumida!E91 -> 362776 | E18: =CEIResumida!F91 -> 917257 | F18: =CEIResumida!G91 -> 0 | G18: =CEIResumida!H91 -> 0 | H18: =CEIResumida!I91 -> 42715 | I18: =CEIResumida!J91 -> 0 | J18: =CEIResumida!K91 -> 511766 | ... L18: =CEIResumida!M91 -> 0
B19: Contribuições sociais | C19: =CEIResumida!D92 -> 0 | D19: =CEIResumida!E92 -> 895266 | E19: =CEIResumida!F92 -> 800730 | F19: =CEIResumida!G92 -> 0 | G19: =CEIResumida!H92 -> 94536 | H19: =CEIResumida!I92 -> 0 | I19: =CEIResumida!J92 -> 0 | J19: =CEIResumida!K92 -> 0 | ... L19: =CEIResumida!M92 -> 0
B20: Benefícios de seguridade social em numerário // Seguro desemprego, bolsa família | C20: =CEIResumida!D93 -> 1254637 | D20: =CEIResumida!E93 -> 0 | E20: =CEIResumida!F93 -> 0 | F20: =CEIResumida!G93 -> 1254637 | G20: =CEIResumida!H93 -> 0 | H20: =CEIResumida!I93 -> 0 | I20: =CEIResumida!J93 -> 0 | J20: =CEIResumida!K93 -> 0 | ... L20: =CEIResumida!M93 -> 0
B21: Outros benefícios de seguro social // Previdência | C21: =CEIResumida!D94 -> 717798 | D21: =CEIResumida!E94 -> 0 | E21: =CEIResumida!F94 -> 0 | F21: =CEIResumida!G94 -> 624646 | G21: =CEIResumida!H94 -> 0 | H21: =CEIResumida!I94 -> 93152 | I21: =CEIResumida!J94 -> 0 | J21: =CEIResumida!K94 -> 0 | ... L21: =CEIResumida!M94 -> 0
B22: Outras transferências correntes | C22: =CEIResumida!D95 -> 35242 | D22: =CEIResumida!E95 -> 0 | E22: =CEIResumida!F95 -> 70054 | F22: =CEIResumida!G95 -> 0 | G22: =CEIResumida!H95 -> 0 | H22: =CEIResumida!I95 -> 13352 | I22: =CEIResumida!J95 -> 0 | J22: =CEIResumida!K95 -> 59170 | ... L22: =CEIResumida!M95 -> 32774
A23: Usos da renda | B23: Consumo final efetivo | C23: =CEIResumida!D96 -> 0 | D23: =CEIResumida!E96 -> 4805004 | E23: =CEIResumida!F96 -> 0 | F23: =CEIResumida!G96 -> 1532204 | G23: =CEIResumida!H96 -> 0 | H23: =CEIResumida!I96 -> 0 | I23: =CEIResumida!J96 -> 0 | J23: =CEIResumida!K96 -> 0 | ... L23: =CEIResumida!M96 -> 0
B24: Ajustamento pela variação dos direitos de pensão | C24: =CEIResumida!D97 -> 0 | D24: =CEIResumida!E97 -> 0 | E24: =CEIResumida!F97 -> 0 | F24: =CEIResumida!G97 -> 0 | G24: =CEIResumida!H97 -> 0 | H24: =CEIResumida!I97 -> 0 | I24: =CEIResumida!J97 -> 0 | J24: =CEIResumida!K97 -> 0 | ... L24: =CEIResumida!M97 -> 0
B25: Formação bruta de capital fixo | C25: =CEIResumida!D98 -> 0 | D25: =CEIResumida!E98 -> 410010 | E25: =CEIResumida!F98 -> 0 | F25: =CEIResumida!G98 -> 139686 | G25: =CEIResumida!H98 -> 0 | H25: =CEIResumida!I98 -> 13718 | I25: =CEIResumida!J98 -> 0 | J25: =CEIResumida!K98 -> 696813 | ... L25: =CEIResumida!M98 -> 0
B26: Variação de estoques | C26: =CEIResumida!D99 -> 0 | D26: =CEIResumida!E99 -> 0 | E26: =CEIResumida!F99 -> 0 | F26: =CEIResumida!G99 -> 0 | G26: =CEIResumida!H99 -> 0 | H26: =CEIResumida!I99 -> 0 | I26: =CEIResumida!J99 -> 0 | J26: =CEIResumida!K99 -> -33878 | ... L26: =CEIResumida!M99 -> 0
B27: Aquisições líquidas de cessões de ativos não-produzidos | C27: =CEIResumida!D100 -> 0 | D27: =CEIResumida!E100 -> 0 | E27: =CEIResumida!F100 -> 0 | F27: =CEIResumida!G100 -> 0 | G27: =CEIResumida!H100 -> 0 | H27: =CEIResumida!I100 -> 0 | I27: =CEIResumida!J100 -> 0 | J27: =CEIResumida!K100 -> 0 | ... L27: =CEIResumida!M100 -> 0
B28: Capacidade (+) / Necessidade(-) líquida de financiamento | C28: =SUM(C7:C27)-SUM(D7:D27) -> 562272 | E28: =SUM(E7:E27)-SUM(F7:F27) -> -918009 | G28: =SUM(G7:G27)-SUM(H7:H27) -> 216917 | I28: =SUM(I7:I27)-SUM(J7:J27) -> 58282 | K28: =SUM(K7:K27)-SUM(L7:L27) -> 80538
B29: Check | C29: 562272 | E29: -918009 | G29: 149429 | I29: 125770 | K29: 80538
C35: S.14 Famílias | E35: S.13 Governo Geral | G35: S.12 Empresas finan- ceiras | I35: S.11 Empresas não- finan- ceiras | K35: Setor externo
C39: Entrada | D39: Saída | E39: Entrada | F39: Saída | G39: Entrada | H39: Saída | I39: Entrada | J39: Saída | K39: Entrada | L39: Saída | N39: VA preço mercado | O39: VA preço básico
B40: Valor adicionado bruto/Produto interno bruto (1) | N40: =G40+I40 -> 0 | O40: =N40-J44 -> 0
A41: Tabela de Usos e Recursos - específico por setor - geração de renda | B41: Salários
B42: Contribuições sociais efetivas
B43: Contribuições sociais inputadas
B44: Impostos, líquidos de subsídios, sobre produtos
B45: Outros impostos, líquidos de subsídios, sobre a produção
A46: Alocação primária do excedente | B46: Juros | C46: =CEIResumida!D86/CEIResumida!D141 -> 0.2591493 | D46: =CEIResumida!E86/CEIResumida!E141 -> 0.085190471 | E46: =CEIResumida!F86/CEIResumida!F141 -> 0.10513893 | F46: =CEIResumida!G86/CEIResumida!G141 -> 0.05816093 | G46: =CEIResumida!H86/CEIResumida!H141 -> 0.076863062 | H46: =CEIResumida!I86/CEIResumida!I141 -> 0.13700196 | I46: =CEIResumida!J86/CEIResumida!J141 -> 0.13780614 | J46: =CEIResumida!K86/CEIResumida!K141 -> 0.073535822 | ... L46: =CEIResumida!M86/CEIResumida!M141 -> 0.019355107
B47: Rendas distribuídas das empresas | C47: =C14/(C14+K14) -> 0.95659084 | H47: =H14/(SUM(G7:G13)-SUM(H7:H13)-H18-H22) -> 0.40065255 | J47: =J14/(SUM(I7:I13)-SUM(J7:J13)-J18-J22) -> 0.71631798 | K47: =1-C47 -> 0.043409158
B48: Lucros reinvestidos de investimento estrangeiro direto
B49: Desembolsos por rendas de investimentos
B50: Renda de recursos naturais
A51: Alocação secundária | B51: Impostos correntes sobre a renda, patrimônio, // Contribuições sociais // Outras transferências | D51: =D18/(SUM(C7:C13)-SUM(D7:D13)) -> 0.11557126 | H51: =H18/(SUM(G7:G13)-SUM(H7:H13)) -> 0.097396527 | J51: =J18/(SUM(I7:I13)-SUM(J7:J13)) -> 0.16438167
B52: Contribuições sociais
...

Sheet Original
A1: Tabela de recursos e usos - 2020 - valores correntes
A3: I - Tabela de recursos de bens e serviços
Y4: Valores correntes em 1 000 000 R$
A5: Descrição do produto | B5: Oferta de bens e serviços | K5: Produção das atividades | X5: Total da economia | Y5: Impor- tação de bens e serviços (2)
B6: Oferta total a preço de con- sumidor | C6: Margem de comércio | D6: Margem de trans- porte | E6: Imposto de impor- tação | F6: IPI | G6: ICMS | H6: Outros impostos menos subsídios | I6: Total de impostos líquidos de subsídios | J6: Oferta total a preço básico | K6: Agrope- cuária | L6: Indústrias extrativas | M6: Indústrias de transfor- mação | N6: Eletricida- de e gás, água, esgoto e gestão de resíduos | O6: Cons- trução | P6: Comércio | Q6: Trans- porte, armaze- nagem e correio | R6: Informação e comu- nicação | S6: Atividades financeiras, de seguros e serviços relacio- nados | T6: Ativi- dades imobi- liárias | U6: Outras atividades de serviços | V6: Adminis- tração, defesa, saúde e educação públicas e seguridade social | W6: Total do produto
A11: Agropecuária | B11: =C11+D11+I11+J11 -> 938989 | C11: 101814 | D11: 17919 | E11: 468 | F11: 0 | G11: 11727 | H11: 6061 | I11: =SUM(E11:H11) -> 18256 | J11: =SUM(W11,Y11) -> 801000 | K11: 777589 | L11: 0 | M11: 0 | N11: 0 | O11: 0 | P11: 172 | Q11: 106 | R11: 0 | S11: 0 | T11: 0 | U11: 0 | V11: 602 | W11: =SUM(K11:V11) -> 778469 | Y11: 22531
A12: Indústrias extrativas | B12: =C12+D12+I12+J12 -> 474641 | C12: 22876 | D12: 8440 | E12: 30 | F12: 0 | G12: 1455 | H12: 3223 | I12: =SUM(E12:H12) -> 4708 | J12: =SUM(W12,Y12) -> 438617 | K12: 317 | L12: 401704 | M12: 1854 | N12: 0 | O12: 0 | P12: 320 | Q12: 0 | R12: 0 | S12: 0 | T12: 0 | U12: 0 | V12: 15 | W12: =SUM(K12:V12) -> 404210 | Y12: 34407
A13: Indústrias de transformação | B13: =C13+D13+I13+J13 -> 6468662 | C13: 1045722 | D13: 71220 | E13: 45158 | F13: 55894 | G13: 379582 | H13: 152570 | I13: =SUM(E13:H13) -> 633204 | J13: =SUM(W13,Y13) -> 4718516 | K13: 9930 | L13: 6125 | M13: 3702844 | N13: 0 | O13: 54 | P13: 91539 | Q13: 147 | R13: 657 | S13: 0 | T13: 0 | U13: 4150 | V13: 2011 | W13: =SUM(K13:V13) -> 3817457 | Y13: 901059
A14: Eletricidade e gás, água, esgoto e gestão de resíduos | B14: =C14+D14+I14+J14 -> 532996 | C14: 4732 | D14: 0 | E14: 0 | F14: 0 | G14: 57829 | H14: 13475 | I14: =SUM(E14:H14) -> 71304 | J14: =SUM(W14,Y14) -> 456960 | K14: 0 | L14: 0 | M14: 0 | N14: 441537 | O14: 0 | P14: 0 | Q14: 0 | R14: 0 | S14: 0 | T14: 0 | U14: 0 | V14: 7972 | W14: =SUM(K14:V14) -> 449509 | Y14: 7451
A15: Construção | B15: =C15+D15+I15+J15 -> 683264 | C15: 0 | D15: 0 | E15: 0 | F15: 0 | G15: 0 | H15: 31512 | I15: =SUM(E15:H15) -> 31512 | J15: =SUM(W15,Y15) -> 651752 | K15: 7719 | L15: 33321 | M15: 0 | N15: 0 | O15: 607286 | P15: 0 | Q15: 0 | R15: 0 | S15: 0 | T15: 0 | U15: 0 | V15: 1 | W15: =SUM(K15:V15) -> 648327 | Y15: 3425
A16: Comércio | B16: =C16+D16+I16+J16 -> 140737 | C16: -1186683 | D16: 0 | E16: 0 | F16: 0 | G16: 0 | H16: 2617 | I16: =SUM(E16:H16) -> 2617 | J16: =SUM(W16,Y16) -> 1324803 | K16: 0 | L16: 32 | M16: 24811 | N16: 34 | O16: 12 | P16: 1288917 | Q16: 830 | R16: 3788 | S16: 0 | T16: 0 | U16: 2678 | V16: 330 | W16: =SUM(K16:V16) -> 1321432 | Y16: 3371
A17: Transporte, armazenagem e correio | B17: =C17+D17+I17+J17 -> 568288 | C17: 0 | D17: -97641 | E17: 0 | F17: 0 | G17: 10588 | H17: 19326 | I17: =SUM(E17:H17) -> 29914 | J17: =SUM(W17,Y17) -> 636015 | K17: 0 | L17: 0 | M17: 0 | N17: 458 | O17: 0 | P17: 3008 | Q17: 611351 | R17: 0 | S17: 0 | T17: 0 | U17: 95 | V17: 4668 | W17: =SUM(K17:V17) -> 619580 | Y17: 16435
A18: Informação e comunicação | B18: =C18+D18+I18+J18 -> 535541 | C18: 11539 | D18: 62 | E18: 12 | F18: 0 | G18: 38831 | H18: 17569 | I18: =SUM(E18:H18) -> 56412 | J18: =SUM(W18,Y18) -> 467528 | K18: 0 | L18: 0 | M18: 0 | N18: 0 | O18: 0 | P18: 1047 | Q18: 48 | R18: 426997 | S18: 1248 | T18: 0 | U18: 137 | V18: 2089 | W18: =SUM(K18:V18) -> 431566 | Y18: 35962
A19: Atividades financeiras, de seguros e serviços relacionados | B19: =C19+D19+I19+J19 -> 800076 | C19: 0 | D19: 0 | E19: 0 | F19: 0 | G19: 0 | H19: 67488 | I19: =SUM(E19:H19) -> 67488 | J19: =SUM(W19,Y19) -> 732588 | K19: 0 | L19: 0 | M19: 0 | N19: 0 | O19: 0 | P19: 0 | Q19: 0 | R19: 0 | S19: 687862 | T19: 0 | U19: 0 | V19: 434 | W19: =SUM(K19:V19) -> 688296 | Y19: 44292
A20: Atividades imobiliárias | B20: =C20+D20+I20+J20 -> 793035 | C20: 0 | D20: 0 | E20: 0 | F20: 0 | G20: 0 | H20: 1248 | I20: =SUM(E20:H20) -> 1248 | J20: =SUM(W20,Y20) -> 791787 | K20: 92 | L20: 670 | M20: 26394 | N20: 12370 | O20: 3762 | P20: 2639 | Q20: 5161 | R20: 1526 | S20: 9080 | T20: 711631 | U20: 8689 | V20: 2641 | W20: =SUM(K20:V20) -> 784655 | Y20: 7132
A21: Outras atividades de serviços | B21: =C21+D21+I21+J21 -> 2125358 | C21: 0 | D21: 0 | E21: 3 | F21: 0 | G21: 23099 | H21: 74895 | I21: =SUM(E21:H21) -> 97997 | J21: =SUM(W21,Y21) -> 2027361 | K21: 114 | L21: 179 | M21: 13473 | N21: 342 | O21: 1387 | P21: 16909 | Q21: 11258 | R21: 2680 | S21: 2713 | T21: 0 | U21: 1797276 | V21: 51086 | W21: =SUM(K21:V21) -> 1897417 | Y21: 129944
A22: Administração, defesa, saúde e educação públicas e seguridade social | B22: =C22+D22+I22+J22 -> 1465281 | C22: 0 | D22: 0 | E22: 0 | F22: 0 | G22: 0 | H22: 0 | I22: =SUM(E22:H22) -> 0 | J22: =SUM(W22,Y22) -> 1465281 | K22: 0 | L22: 0 | M22: 0 | N22: 0 | O22: 0 | P22: 0 | Q22: 0 | R22: 0 | S22: 0 | T22: 0 | U22: 0 | V22: 1465281 | W22: =SUM(K22:V22) -> 1465281 | Y22: 0
A24: Total | B24: =SUM(B11:B22) -> 15526868 | C24: =SUM(C11:C22) -> 0 | D24: =SUM(D11:D22) -> 0 | E24: =SUM(E11:E22) -> 45671 | F24: =SUM(F11:F22) -> 55894 | G24: =SUM(G11:G22) -> 523111 | H24: =SUM(H11:H22) -> 389984 | I24: =SUM(I11:I22) -> 1014660 | ... W24: =SUM(W11:W22) -> 13306199 | Y24: =SUM(Y11:Y23) -> 1206009
A26: Fonte: IBGE, Diretoria de Pesquisas, Coordenação de Contas Nacionais.
A31: II - Tabela de usos de bens e serviços
AF32: Valores correntes em 1 000 000 R$
A33: Descrição do produto | B33: Oferta total a preço de con- sumidor | C33: Margem de comércio | D33: Margem de trans- porte | E33: Imposto de impor- tação | F33: IPI | G33: ICMS | H33: Outros impostos | I33: Total de impostos | J33: Oferta total a preço básico | K33: Consumo intermediário das atividades | X33: PIB / Total da economia (1) | Y33: Demanda final | AF33: De- manda total
K34: Agrope- cuária | L34: Indústrias extrativas | M34: Indústrias de transfor- mação | N34: Eletricida- de e gás, água, esgoto e gestão de resíduos | O34: Cons- trução | P34: Comércio | Q34: Trans- porte, armaze- nagem e correio | R34: Informação e comu- nicação | S34: Atividades financeiras, de seguros e serviços relacio- nados | T34: Ativi- dades imobi- liárias | U34: Outras atividades de serviços | V34: Adminis- tração, defesa, saúde e educação públicas e seguridade social | W34: Total do produto | Y34: Expor- tação de bens e serviços (3) | Z34: Consu- mo do governo | AA34: Consu- mo das ISFLSF | AB34: Consu- mo das famílias | AC34: Forma- ção bruta de capi- tal fixo | AD34: Varia- ção de estoque | AE34: De- manda final
A39: Agropecuária | B39: =B11 -> 938989 | K39: 46529 | L39: 2 | M39: 385354 | N39: 69 | O39: 1088 | P39: 16888 | Q39: 0 | R39: 0 | S39: 0 | T39: 0 | U39: 11153 | V39: 3683 | W39: =SUM(K39:V39) -> 464766 | Y39: 241683 | Z39: 230 | AA39: 0 | AB39: =SUM(AH39:AI39) -> 212694 | AC39: 22310 | AD39: -2694 | AE39: =SUM(Y39:AD39) -> 474223 | AF39: =W39+AE39 -> 938989 | AH39: 0 | AI39: 212694 | AK39: =AE39-AB39 -> 261529
A40: Indústrias extrativas | B40: =B12 -> 474641 | K40: 874 | L40: 16121 | M40: 198222 | N40: 12854 | O40: 9589 | P40: 121 | Q40: 6 | R40: 0 | S40: 0 | T40: 551 | U40: 86 | V40: 149 | W40: =SUM(K40:V40) -> 238573 | Y40: 253114 | Z40: 0 | AA40: 0 | AB40: =SUM(AH40:AI40) -> 0 | AC40: 10455 | AD40: -27501 | AE40: =SUM(Y40:AD40) -> 236068 | AF40: =W40+AE40 -> 474641 | AH40: 0 | AI40: 0 | AK40: =AE40-AB40 -> 236068
A41: Indústrias de transformação | B41: =B13 -> 6468662 | K41: 264935 | L41: 117877 | M41: 1817709 | N41: 39415 | O41: 232483 | P41: 143692 | Q41: 168628 | R41: 24714 | S41: 9572 | T41: 11292 | U41: 261506 | V41: 85762 | W41: =SUM(K41:V41) -> 3177585 | Y41: 611468 | Z41: 9716 | AA41: 0 | AB41: =SUM(AH41:AI41) -> 2148705 | AC41: 523356 | AD41: -2168 | AE41: =SUM(Y41:AD41) -> 3291077 | AF41: =W41+AE41 -> 6468662 | AH41: 0 | AI41: 2148705 | AK41: =AE41-AB41 -> 1142372
A42: Eletricidade e gás, água, esgoto e gestão de resíduos | B42: =B14 -> 532996 | K42: 19060 | L42: 4165 | M42: 57562 | N42: 142663 | O42: 1100 | P42: 35518 | Q42: 5222 | R42: 4434 | S42: 3647 | T42: 1676 | U42: 44360 | V42: 27071 | W42: =SUM(K42:V42) -> 346478 | Y42: 2 | Z42: 0 | AA42: 0 | AB42: =SUM(AH42:AI42) -> 186576 | AC42: 0 | AD42: -60 | AE42: =SUM(Y42:AD42) -> 186518 | AF42: =W42+AE42 -> 532996 | AH42: 0 | AI42: 186576 | AK42: =AE42-AB42 -> -58
A43: Construção | B43: =B15 -> 683264 | K43: 346 | L43: 7040 | M43: 3483 | N43: 6090 | O43: 64476 | P43: 1281 | Q43: 2108 | R43: 5076 | S43: 1156 | T43: 2074 | U43: 5894 | V43: 24150 | W43: =SUM(K43:V43) -> 123174 | Y43: 3481 | Z43: 0 | AA43: 0 | AB43: =SUM(AH43:AI43) -> 0 | AC43: 556609 | AD43: 0 | AE43: =SUM(Y43:AD43) -> 560090 | AF43: =W43+AE43 -> 683264 | AH43: 0 | AI43: 0 | AK43: =AE43-AB43 -> 560090
A44: Comércio | B44: =B16 -> 140737 | K44: 353 | L44: 2486 | M44: 43753 | N44: 1300 | O44: 493 | P44: 12404 | Q44: 8467 | R44: 3711 | S44: 146 | T44: 25 | U44: 3481 | V44: 3530 | W44: =SUM(K44:V44) -> 80149 | Y44: 4676 | Z44: 0 | AA44: 0 | AB44: =SUM(AH44:AI44) -> 55912 | AC44: 0 | AD44: 0 | AE44: =SUM(Y44:AD44) -> 60588 | AF44: =W44+AE44 -> 140737 | AH44: 0 | AI44: 55912 | AK44: =AE44-AB44 -> 4676
A45: Transporte, armazenagem e correio | B45: =B17 -> 568288 | K45: 12900 | L45: 36580 | M45: 150873 | N45: 5229 | O45: 3050 | P45: 81866 | Q45: 90333 | R45: 2762 | S45: 5947 | T45: 329 | U45: 22063 | V45: 12154 | W45: =SUM(K45:V45) -> 424086 | Y45: 34419 | Z45: 0 | AA45: 0 | AB45: =SUM(AH45:AI45) -> 109783 | AC45: 0 | AD45: 0 | AE45: =SUM(Y45:AD45) -> 144202 | AF45: =W45+AE45 -> 568288 | AH45: 0 | AI45: 109783 | AK45: =AE45-AB45 -> 34419
A46: Informação e comunicação | B46: =B18 -> 535541 | K46: 63 | L46: 1830 | M46: 22246 | N46: 3243 | O46: 1755 | P46: 25118 | Q46: 6656 | R46: 56654 | S46: 34169 | T46: 1273 | U46: 77971 | V46: 37213 | W46: =SUM(K46:V46) -> 268191 | Y46: 15282 | Z46: 0 | AA46: 0 | AB46: =SUM(AH46:AI46) -> 152610 | AC46: 100913 | AD46: -1455 | AE46: =SUM(Y46:AD46) -> 267350 | AF46: =W46+AE46 -> 535541 | AH46: 0 | AI46: 152610 | AK46: =AE46-AB46 -> 114740
A47: Atividades financeiras, de seguros e serviços relacionados | B47: =B19 -> 800076 | K47: 12145 | L47: 8823 | M47: 68105 | N47: 11655 | O47: 9620 | P47: 37998 | Q47: 16729 | R47: 14335 | S47: 111389 | T47: 28083 | U47: 31616 | V47: 60811 | W47: =SUM(K47:V47) -> 411309 | Y47: 6943 | Z47: 2165 | AA47: 0 | AB47: =SUM(AH47:AI47) -> 379659 | AC47: 0 | AD47: 0 | AE47: =SUM(Y47:AD47) -> 388767 | AF47: =W47+AE47 -> 800076 | AH47: 0 | AI47: 379659 | AK47: =AE47-AB47 -> 9108
A48: Atividades imobiliárias | B48: =B20 -> 793035 | K48: 27 | L48: 745 | M48: 8979 | N48: 1618 | O48: 1498 | P48: 59453 | Q48: 6412 | R48: 6456 | S48: 6844 | T48: 2942 | U48: 45392 | V48: 4778 | W48: =SUM(K48:V48) -> 145144 | Y48: 4688 | Z48: 0 | AA48: 0 | AB48: =SUM(AH48:AI48) -> 643203 | AC48: 0 | AD48: 0 | AE48: =SUM(Y48:AD48) -> 647891 | AF48: =W48+AE48 -> 793035 | AH48: 0 | AI48: 643203 | AK48: =AE48-AB48 -> 4688
A49: Outras atividades de serviços | B49: =B21 -> 2125358 | K49: 3908 | L49: 52747 | M49: 199401 | N49: 21493 | O49: 19428 | P49: 164866 | Q49: 51101 | R49: 79932 | S49: 73483 | T49: 7373 | U49: 227146 | V49: 130929 | W49: =SUM(K49:V49) -> 1031807 | Y49: 76293 | Z49: 54812 | AA49: 0 | AB49: =SUM(AH49:AI49) -> 915862 | AC49: 46584 | AD49: 0 | AE49: =SUM(Y49:AD49) -> 1093551 | AF49: =W49+AE49 -> 2125358 | AH49: 104919 | AI49: 810943 | AK49: =AE49-AB49 -> 177689
A50: Administração, defesa, saúde e educação públicas e seguridade social | B50: =B22 -> 1465281 | K50: 0 | L50: 0 | M50: 0 | N50: 0 | O50: 0 | P50: 0 | Q50: 0 | R50: 0 | S50: 0 | T50: 0 | U50: 0 | V50: 0 | W50: =SUM(K50:V50) -> 0 | Y50: 0 | Z50: 1465281 | AA50: 0 | AB50: =SUM(AH50:AI50) -> 0 | AC50: 0 | AD50: 0 | AE50: =SUM(Y50:AD50) -> 1465281 | AF50: =W50+AE50 -> 1465281 | AH50: 0 | AI50: 0 | AK50: =AE50-AB50 -> 1465281
A51: Total | B51: =SUM(B39:B50) -> 15526868 | K51: =SUM(K39:K50) -> 361140 | L51: =SUM(L39:L50) -> 248416 | M51: =SUM(M39:M50) -> 2955687 | N51: =SUM(N39:N50) -> 245629 | O51: =SUM(O39:O50) -> 344580 | P51: =SUM(P39:P50) -> 579205 | Q51: =SUM(Q39:Q50) -> 355662 | R51: =SUM(R39:R50) -> 198074 | ... V51: =SUM(V39:V50) -> 390230 | W51: =SUM(K51:V51) -> 6711262 | Y51: =SUM(Y39:Y50) -> 1252049 | Z51: =SUM(Z39:Z50) -> 1532204 | AA51: =SUM(AA39:AA50) -> 0 | AB51: =SUM(AH51:AI51) -> 4805004 | AC51: =SUM(AC39:AC50) -> 1260227 | AD51: =SUM(AD39:AD50) -> -33878 | AE51: =SUM(Y51:AD51) -> 8815606 | AF51: =W51+AE51 -> 15526868 | AH51: =SUM(AH39:AH50) -> 104919 | AI51: =SUM(AI39:AI50) -> 4700085 | AK51: =AE51-AB51 -> 4010602
A52: Componentes do valor adicionado
A54: Valor adicionado bruto ( PIB ) | I54: =I24 -> 1014660 | K54: =K24-K51 -> 434621 | L54: =L24-L51 -> 193615 | M54: =M24-M51 -> 813689 | N54: =N24-N51 -> 209112 | O54: =O24-O51 -> 267921 | P54: =P24-P51 -> 825346 | Q54: =Q24-Q51 -> 273239 | R54: =R24-R51 -> 237574 | ... V54: =V24-V51 -> 1146900 | W54: =SUM(K54:V54) -> 6594937 | X54: =I54+W54 -> 7609597
A55: Remunerações | K55: 56426 | L55: 31030 | M55: 431907 | N55: 42340 | O55: 110214 | P55: 404268 | Q55: 144416 | R55: 106305 | S55: 181285 | T55: 9024 | U55: 646179 | V55: 1028949 | W55: =SUM(K55:V55) -> 3192343 | X55: =I55+W55 -> 3192343 | AA55: TABELA DE RECURSOS E USOS
A56: Salários | K56: 48460 | L56: 23545 | M56: 342665 | N56: 31380 | O56: 90262 | P56: 322109 | Q56: 115820 | R56: 84430 | S56: 140274 | T56: 7050 | U56: 545236 | V56: 780730 | W56: =SUM(K56:V56) -> 2531961 | X56: =I56+W56 -> 2531961
...

Sheet ParâmeetrosTRU
A1: Tabela de recursos e usos - 2020 - valores correntes
A3: I - Tabela de recursos de bens e serviços
Y4: Valores correntes em 1 000 000 R$
A5: Descrição do produto | B5: Oferta de bens e serviços | K5: Produção das atividades | X5: Total da economia | Y5: Impor- tação de bens e serviços (2)
B6: Oferta total a preço de con- sumidor | C6: Margem de comércio | D6: Margem de trans- porte | E6: Imposto de impor- tação | F6: IPI | G6: ICMS | H6: Outros impostos menos subsídios | I6: Total de impostos líquidos de subsídios | J6: Oferta total a preço básico | K6: Agrope- cuária | L6: Indústrias extrativas | M6: Indústrias de transfor- mação | N6: Eletricida- de e gás, água, esgoto e gestão de resíduos | O6: Cons- trução | P6: Comércio | Q6: Trans- porte, armaze- nagem e correio | R6: Informação e comu- nicação | S6: Atividades financeiras, de seguros e serviços relacio- nados | T6: Ativi- dades imobi- liárias | U6: Outras atividades de serviços | V6: Adminis- tração, defesa, saúde e educação públicas e seguridade social | W6: Total do produto
A11: Agropecuária | B11: =C11+D11+I11+J11 -> 1 | C11: =Original!C11/Original!$B11 -> 0.10842939 | D11: =Original!D11/Original!$B11 -> 0.019083291 | I11: =Original!I11/Original!$B11 -> 0.019442187 | J11: =Original!J11/Original!$B11 -> 0.85304514 | K11: =Original!K11/Original!$B11 -> 0.828113 | L11: =Original!L11/Original!$B11 -> 0 | M11: =Original!M11/Original!$B11 -> 0 | N11: =Original!N11/Original!$B11 -> 0 | O11: =Original!O11/Original!$B11 -> 0 | P11: =Original!P11/Original!$B11 -> 0.00018317573 | ... V11: =Original!V11/Original!$B11 -> 0.00064111507 | X11: =Original!X11/Original!$B11 -> 0 | Y11: =Original!Y11/Original!$B11 -> 0.023994956
A12: Indústrias extrativas | B12: =C12+D12+I12+J12 -> 1 | C12: =Original!C12/Original!$B12 -> 0.048196426 | D12: =Original!D12/Original!$B12 -> 0.01778186 | E12: =Original!E12/Original!$B12 -> 6.3205665e-05 | F12: =Original!F12/Original!$B12 -> 0 | G12: =Original!G12/Original!$B12 -> 0.0030654747 | H12: =Original!H12/Original!$B12 -> 0.0067903953 | I12: =Original!I12/Original!$B12 -> 0.0099190757 | J12: =Original!J12/Original!$B12 -> 0.92410264 | ... V12: =Original!V12/Original!$B12 -> 3.1602832e-05 | X12: =Original!X12/Original!$B12 -> 0 | Y12: =Original!Y12/Original!$B12 -> 0.072490577
A13: Indústrias de transformação | B13: =C13+D13+I13+J13 -> 1 | C13: =Original!C13/Original!$B13 -> 0.16165971 | D13: =Original!D13/Original!$B13 -> 0.011010005 | E13: =Original!E13/Original!$B13 -> 0.0069810418 | F13: =Original!F13/Original!$B13 -> 0.0086407359 | G13: =Original!G13/Original!$B13 -> 0.058680141 | H13: =Original!H13/Original!$B13 -> 0.023586021 | I13: =Original!I13/Original!$B13 -> 0.09788794 | J13: =Original!J13/Original!$B13 -> 0.72944235 | ... V13: =Original!V13/Original!$B13 -> 0.00031088346 | X13: =Original!X13/Original!$B13 -> 0 | Y13: =Original!Y13/Original!$B13 -> 0.13929604
A14: Eletricidade e gás, água, esgoto e gestão de resíduos | B14: =C14+D14+I14+J14 -> 1 | C14: =Original!C14/Original!$B14 -> 0.0088781154 | D14: =Original!D14/Original!$B14 -> 0 | E14: =Original!E14/Original!$B14 -> 0 | F14: =Original!F14/Original!$B14 -> 0 | G14: =Original!G14/Original!$B14 -> 0.108498 | H14: =Original!H14/Original!$B14 -> 0.025281616 | I14: =Original!I14/Original!$B14 -> 0.13377962 | J14: =Original!J14/Original!$B14 -> 0.85734227 | ... V14: =Original!V14/Original!$B14 -> 0.01495696 | X14: =Original!X14/Original!$B14 -> 0 | Y14: =Original!Y14/Original!$B14 -> 0.013979467
A15: Construção | B15: =C15+D15+I15+J15 -> 1 | C15: =Original!C15/Original!$B15 -> 0 | D15: =Original!D15/Original!$B15 -> 0 | E15: =Original!E15/Original!$B15 -> 0 | F15: =Original!F15/Original!$B15 -> 0 | G15: =Original!G15/Original!$B15 -> 0 | H15: =Original!H15/Original!$B15 -> 0.046119801 | I15: =Original!I15/Original!$B15 -> 0.046119801 | J15: =Original!J15/Original!$B15 -> 0.9538802 | ... V15: =Original!V15/Original!$B15 -> 1.4635631e-06 | X15: =Original!X15/Original!$B15 -> 0 | Y15: =Original!Y15/Original!$B15 -> 0.0050127037
A16: Comércio | B16: =C16+D16+I16+J16 -> 1 | C16: =Original!C16/Original!$B16 -> -8.4319191 | D16: =Original!D16/Original!$B16 -> 0 | E16: =Original!E16/Original!$B16 -> 0 | F16: =Original!F16/Original!$B16 -> 0 | G16: =Original!G16/Original!$B16 -> 0 | H16: =Original!H16/Original!$B16 -> 0.018594968 | I16: =Original!I16/Original!$B16 -> 0.018594968 | J16: =Original!J16/Original!$B16 -> 9.4133241 | ... V16: =Original!V16/Original!$B16 -> 0.0023447992 | X16: =Original!X16/Original!$B16 -> 0 | Y16: =Original!Y16/Original!$B16 -> 0.023952479
A17: Transporte, armazenagem e correio | B17: =C17+D17+I17+J17 -> 1 | C17: =Original!C17/Original!$B17 -> 0 | D17: =Original!D17/Original!$B17 -> -0.17181605 | E17: =Original!E17/Original!$B17 -> 0 | F17: =Original!F17/Original!$B17 -> 0 | G17: =Original!G17/Original!$B17 -> 0.018631398 | H17: =Original!H17/Original!$B17 -> 0.034007405 | I17: =Original!I17/Original!$B17 -> 0.052638803 | J17: =Original!J17/Original!$B17 -> 1.1191772 | ... V17: =Original!V17/Original!$B17 -> 0.0082141449 | X17: =Original!X17/Original!$B17 -> 0 | Y17: =Original!Y17/Original!$B17 -> 0.028920195
A18: Informação e comunicação | B18: =C18+D18+I18+J18 -> 1 | C18: =Original!C18/Original!$B18 -> 0.021546436 | D18: =Original!D18/Original!$B18 -> 0.00011577078 | E18: =Original!E18/Original!$B18 -> 2.2407248e-05 | F18: =Original!F18/Original!$B18 -> 0 | G18: =Original!G18/Original!$B18 -> 0.072507987 | H18: =Original!H18/Original!$B18 -> 0.032806078 | I18: =Original!I18/Original!$B18 -> 0.10533647 | J18: =Original!J18/Original!$B18 -> 0.87300132 | ... V18: =Original!V18/Original!$B18 -> 0.0039007284 | X18: =Original!X18/Original!$B18 -> 0 | Y18: =Original!Y18/Original!$B18 -> 0.067150788
A19: Atividades financeiras, de seguros e serviços relacionados | B19: =C19+D19+I19+J19 -> 1 | C19: =Original!C19/Original!$B19 -> 0 | D19: =Original!D19/Original!$B19 -> 0 | E19: =Original!E19/Original!$B19 -> 0 | F19: =Original!F19/Original!$B19 -> 0 | G19: =Original!G19/Original!$B19 -> 0 | H19: =Original!H19/Original!$B19 -> 0.084351987 | I19: =Original!I19/Original!$B19 -> 0.084351987 | J19: =Original!J19/Original!$B19 -> 0.91564801 | ... V19: =Original!V19/Original!$B19 -> 0.00054244847 | X19: =Original!X19/Original!$B19 -> 0 | Y19: =Original!Y19/Original!$B19 -> 0.055359741
A20: Atividades imobiliárias | B20: =C20+D20+I20+J20 -> 1 | C20: =Original!C20/Original!$B20 -> 0 | D20: =Original!D20/Original!$B20 -> 0 | E20: =Original!E20/Original!$B20 -> 0 | F20: =Original!F20/Original!$B20 -> 0 | G20: =Original!G20/Original!$B20 -> 0 | H20: =Original!H20/Original!$B20 -> 0.001573701 | I20: =Original!I20/Original!$B20 -> 0.001573701 | J20: =Original!J20/Original!$B20 -> 0.9984263 | ... V20: =Original!V20/Original!$B20 -> 0.0033302439 | X20: =Original!X20/Original!$B20 -> 0 | Y20: =Original!Y20/Original!$B20 -> 0.0089932979
A21: Outras atividades de serviços | B21: =C21+D21+I21+J21 -> 1 | C21: =Original!C21/Original!$B21 -> 0 | D21: =Original!D21/Original!$B21 -> 0 | E21: =Original!E21/Original!$B21 -> 1.4115269e-06 | F21: =Original!F21/Original!$B21 -> 0 | G21: =Original!G21/Original!$B21 -> 0.010868287 | H21: =Original!H21/Original!$B21 -> 0.035238769 | I21: =Original!I21/Original!$B21 -> 0.046108467 | J21: =Original!J21/Original!$B21 -> 0.95389153 | ... V21: =Original!V21/Original!$B21 -> 0.024036421 | X21: =Original!X21/Original!$B21 -> 0 | Y21: =Original!Y21/Original!$B21 -> 0.061139817
A22: Administração, defesa, saúde e educação públicas e seguridade social | B22: =C22+D22+I22+J22 -> 1 | C22: =Original!C22/Original!$B22 -> 0 | D22: =Original!D22/Original!$B22 -> 0 | E22: =Original!E22/Original!$B22 -> 0 | F22: =Original!F22/Original!$B22 -> 0 | G22: =Original!G22/Original!$B22 -> 0 | H22: =Original!H22/Original!$B22 -> 0 | I22: =Original!I22/Original!$B22 -> 0 | J22: =Original!J22/Original!$B22 -> 1 | ... V22: =Original!V22/Original!$B22 -> 1 | X22: =Original!X22/Original!$B22 -> 0 | Y22: =Original!Y22/Original!$B22 -> 0
A24: Total | B24: =C24+D24+I24+J24 -> 1 | C24: =Original!C24/Original!$B24 -> 0 | D24: =Original!D24/Original!$B24 -> 0 | E24: =Original!E24/Original!$B24 -> 0.0029414174 | F24: =Original!F24/Original!$B24 -> 0.0035998245 | G24: =Original!G24/Original!$B24 -> 0.033690697 | H24: =Original!H24/Original!$B24 -> 0.02511672 | I24: =Original!I24/Original!$B24 -> 0.065348659 | J24: =Original!J24/Original!$B24 -> 0.93465134 | ... V24: =Original!V24/Original!$B24 -> 0.098998072 | X24: =Original!X24/Original!$B24 -> 0 | Y24: =Original!Y24/Original!$B24 -> 0.077672393
A26: Fonte: IBGE, Diretoria de Pesquisas, Coordenação de Contas Nacionais.
A31: II - Tabela de usos de bens e serviços
AF32: Valores correntes em 1 000 000 R$
A33: Descrição do produto | B33: Oferta total a preço de con- sumidor | C33: Margem de comércio | D33: Margem de trans- porte | E33: Imposto de impor- tação | F33: IPI | G33: ICMS | H33: Outros impostos | I33: Total de impostos | J33: Oferta total a preço básico | K33: Consumo intermediário das atividades | X33: PIB / Total da economia (1) | Y33: Demanda final | AF33: De- manda total
